Workbook

Sheet AGRICORP
C1: 2022 | D1: 2021 | E1: 2020 | F1: 2019 | I1: Comptes de gestion
A2: 10100000 | B2: Capital | C2: =IF(A2=A1,0,SUMIFS(BLG1222!$I:$I,BLG1222!$A:$A,"agricorp",BLG1222!$D:$D,A:A)) -> 0 | D2: -10000000 | E2: -2000000 | F2: -2000000 | I2: 10100000 | J2: Capital
A3: 11900000 | B3: RAN débiteur | C3: =IF(A3=A2,0,SUMIFS(BLG1222!$I:$I,BLG1222!$A:$A,"agricorp",BLG1222!$D:$D,A:A)) -> 0 | D3: 2419584.2 | E3: 2419584.2 | F3: 2106451.2 | I3: 11900000 | J3: RAN débiteur
A4: 12000000 | B4: Resultat net de l'exercice benefice | C4: =IF(A4=A3,0,SUMIFS(BLG1222!$I:$I,BLG1222!$A:$A,"agricorp",BLG1222!$D:$D,A:A)) -> 0 | D4: 280428.55 | I4: 12000000 | J4: Resultat net de l'exercice benefice
A5: 12900000 | B5: Resultat net de exercice perte | C5: =IF(A5=A4,0,SUMIFS(BLG1222!$I:$I,BLG1222!$A:$A,"agricorp",BLG1222!$D:$D,A:A)) -> 0 | I5: 12900000 | J5: Resultat net de exercice perte
A6: 20400000 | B6: Logiciels informatiques & assimilés | C6: =IF(A6=A5,0,SUMIFS(BLG1222!$I:$I,BLG1222!$A:$A,"agricorp",BLG1222!$D:$D,A:A)) -> 0 | I6: 20400000 | J6: Logiciels informatiques & assimilés
A7: 21500000 | B7: AAI batiments | C7: =IF(A7=A6,0,SUMIFS(BLG1222!$I:$I,BLG1222!$A:$A,"agricorp",BLG1222!$D:$D,A:A)) -> 0 | D7: 3128790 | I7: 21500000 | J7: AAI batiments
A8: 21510000 | B8: AAI-Autres que bâtiments | C8: =IF(A8=A7,0,SUMIFS(BLG1222!$I:$I,BLG1222!$A:$A,"agricorp",BLG1222!$D:$D,A:A)) -> 0 | D8: 2808000 | I8: 21510000 | J8: AAI-Autres que bâtiments
A9: 21800000 | B9: Matériels et mob de logement | C9: =IF(A9=A8,0,SUMIFS(BLG1222!$I:$I,BLG1222!$A:$A,"agricorp",BLG1222!$D:$D,A:A)) -> 0 | D9: 10847965 | I9: 21800000 | J9: Matériels et mob de logement
A10: 21810000 | B10: Matériels & outillages | C10: =IF(A10=A9,0,SUMIFS(BLG1222!$I:$I,BLG1222!$A:$A,"agricorp",BLG1222!$D:$D,A:A)) -> 0 | I10: 21811000 | J10: Matériels & outillages
A11: 21820000 | B11: MMB | C11: =IF(A11=A10,0,SUMIFS(BLG1222!$I:$I,BLG1222!$A:$A,"agricorp",BLG1222!$D:$D,A:A)) -> 0 | D11: 25009519 | I11: 21820000 | J11: MMB
A12: 21830000 | B12: Materiel de transport | C12: =IF(A12=A11,0,SUMIFS(BLG1222!$I:$I,BLG1222!$A:$A,"agricorp",BLG1222!$D:$D,A:A)) -> 0 | D12: 22154000 | I12: 21830000 | J12: Materiel de transport
A13: 21840000 | B13: Matériel informatiques | C13: =IF(A13=A12,0,SUMIFS(BLG1222!$I:$I,BLG1222!$A:$A,"agricorp",BLG1222!$D:$D,A:A)) -> 0 | D13: 1.5531039e+08 | I13: 21840000 | J13: Matériel informatiques
A14: 26100000 | B14: Titres de participations | C14: =IF(A14=A13,0,SUMIFS(BLG1222!$I:$I,BLG1222!$A:$A,"agricorp",BLG1222!$D:$D,A:A)) -> 0 | D14: 3980000 | E14: 3980000 | F14: 3980000 | I14: 26100000 | J14: Titres de participations
A15: 27500000 | B15: Depot & cautionnements verses | C15: =IF(A15=A14,0,SUMIFS(BLG1222!$I:$I,BLG1222!$A:$A,"agricorp",BLG1222!$D:$D,A:A)) -> 0 | I15: 27500000 | J15: Depot & cautionnements verses
A16: 28150000 | B16: Amts Amenagement batiments | C16: =IF(A16=A15,0,SUMIFS(BLG1222!$I:$I,BLG1222!$A:$A,"agricorp",BLG1222!$D:$D,A:A)) -> 0 | D16: -13036.63 | I16: 28150000 | J16: Amts Amenagement batiments
A17: 28151000 | B17: Amortt agenc-amengt- autres que bât | C17: =IF(A17=A16,0,SUMIFS(BLG1222!$I:$I,BLG1222!$A:$A,"agricorp",BLG1222!$D:$D,A:A)) -> 0 | D17: -23400 | I17: 28151000 | J17: Amortt agenc-amengt- autres que bât
A18: 28182000 | B18: Amts MMB | C18: =IF(A18=A17,0,SUMIFS(BLG1222!$I:$I,BLG1222!$A:$A,"agricorp",BLG1222!$D:$D,A:A)) -> 0 | D18: -899873.34 | I18: 28182000 | J18: Amts MMB
A19: 28183000 | B19: AMT matériel de transport | C19: =IF(A19=A18,0,SUMIFS(BLG1222!$I:$I,BLG1222!$A:$A,"agricorp",BLG1222!$D:$D,A:A)) -> 0 | D19: -778590.28 | I19: 28183000 | J19: AMT matériel de transport
A20: 28184000 | B20: Amts materiel informatique | C20: =IF(A20=A19,0,SUMIFS(BLG1222!$I:$I,BLG1222!$A:$A,"agricorp",BLG1222!$D:$D,A:A)) -> 0 | D20: -16381200 | I20: 28184000 | J20: Amts materiel informatique
A21: 28185000 | B21: Amts mat & mob de logt | C21: =IF(A21=A20,0,SUMIFS(BLG1222!$I:$I,BLG1222!$A:$A,"agricorp",BLG1222!$D:$D,A:A)) -> 0 | D21: -146986.45 | I21: 28185000 | J21: Amts mat & mob de logt
A22: 40100000 | B22: Fournisseurs locaux | C22: =IF(A22=A21,0,SUMIFS(BLG1222!$I:$I,BLG1222!$A:$A,"agricorp",BLG1222!$D:$D,A:A)) -> 0 | D22: -2.2166698e+08 | I22: 40100000 | J22: Fournisseurs locaux
A23: 40120000 | B23: Fournisseurs étrangers | C23: =IF(A23=A22,0,SUMIFS(BLG1222!$I:$I,BLG1222!$A:$A,"agricorp",BLG1222!$D:$D,A:A)) -> 0 | I23: 40120000 | J23: FRNS ETRANGERS
A24: 40340000 | B24: F/sseurs effets à payer BNI | C24: =IF(A24=A23,0,SUMIFS(BLG1222!$I:$I,BLG1222!$A:$A,"agricorp",BLG1222!$D:$D,A:A)) -> 0 | I24: 40340000 | J24: F/SSEURS EFFETS À PAYER BNI
A25: 40800000 | B25: F/sseurs fact à recevoir | C25: =IF(A25=A24,0,SUMIFS(BLG1222!$I:$I,BLG1222!$A:$A,"agricorp",BLG1222!$D:$D,A:A)) -> 0 | D25: -17262815 | I25: 40800000 | J25: F/sseurs fact à recevoir
A26: 40900000 | B26: Frns: avance et acomptes | C26: =IF(A26=A25,0,SUMIFS(BLG1222!$I:$I,BLG1222!$A:$A,"agricorp",BLG1222!$D:$D,A:A)) -> 0 | D26: 4073000.2 | I26: 40900000 | J26: Frns: avance et acomptes
A27: 41100000 | B27: Collectifs clients | C27: =IF(A27=A26,0,SUMIFS(BLG1222!$I:$I,BLG1222!$A:$A,"agricorp",BLG1222!$D:$D,A:A)) -> 0 | I27: 41100000 | J27: Collectifs clients
A28: 41810000 | B28: Clients: factures à établir | C28: =IF(A28=A27,0,SUMIFS(BLG1222!$I:$I,BLG1222!$A:$A,"agricorp",BLG1222!$D:$D,A:A)) -> 0 | D28: 2.5037272e+08 | I28: 41810000 | J28: Clients: factures à établir
A29: 42100000 | B29: Rémunérations dues au personnel | C29: =IF(A29=A28,0,SUMIFS(BLG1222!$I:$I,BLG1222!$A:$A,"agricorp",BLG1222!$D:$D,A:A)) -> 0 | D29: 1109807.8 | I29: 42100000 | J29: Rémunérations dues au personnel
A30: 42500000 | B30: Avances & acomptes au personnel | C30: =IF(A30=A29,0,SUMIFS(BLG1222!$I:$I,BLG1222!$A:$A,"agricorp",BLG1222!$D:$D,A:A)) -> 0 | I30: 42500000 | J30: AVANCES & ACOMPTESAU PERSONNEL
A31: 42520000 | B31: Avances spéciales | C31: =IF(A31=A30,0,SUMIFS(BLG1222!$I:$I,BLG1222!$A:$A,"agricorp",BLG1222!$D:$D,A:A)) -> 0 | D31: 380983.63 | I31: 42520000 | J31: Avances spéciales
A32: 42540000 | B32: Tsinjo FAMENO | C32: =IF(A32=A31,0,SUMIFS(BLG1222!$I:$I,BLG1222!$A:$A,"agricorp",BLG1222!$D:$D,A:A)) -> 0 | D32: -7095999.9 | I32: 42540000 | J32: Tsinjo FAMENO
A33: 43100000 | B33: CNaPS | C33: =IF(A33=A32,0,SUMIFS(BLG1222!$I:$I,BLG1222!$A:$A,"agricorp",BLG1222!$D:$D,A:A)) -> 0 | D33: -84746315 | I33: 43100000 | J33: CNaPS
A34: 43110000 | B34: Allocation familiale CNAPS | C34: =IF(A34=A33,0,SUMIFS(BLG1222!$I:$I,BLG1222!$A:$A,"agricorp",BLG1222!$D:$D,A:A)) -> 0 | D34: -348000 | I34: 43110000 | J34: Allocation familiale CNAPS
A35: 43200000 | B35: OSTIE | C35: =IF(A35=A34,0,SUMIFS(BLG1222!$I:$I,BLG1222!$A:$A,"agricorp",BLG1222!$D:$D,A:A)) -> 0 | D35: -36319849 | I35: 43200000 | J35: OSTIE
A36: 43300000 | B36: FMFP | C36: =IF(A36=A35,0,SUMIFS(BLG1222!$I:$I,BLG1222!$A:$A,"agricorp",BLG1222!$D:$D,A:A)) -> 0 | D36: -6053308.2 | I36: 43300000 | J36: FMFP
A37: 43400000 | B37: ASCOMA | C37: =IF(A37=A36,0,SUMIFS(BLG1222!$I:$I,BLG1222!$A:$A,"agricorp",BLG1222!$D:$D,A:A)) -> 0 | D37: -700000 | I37: 43400000 | J37: ASCOMA
A38: 44100000 | B38: Etat: IRSA à payer | C38: =IF(A38=A37,0,SUMIFS(BLG1222!$I:$I,BLG1222!$A:$A,"agricorp",BLG1222!$D:$D,A:A)) -> 0 | D38: -75838460 | I38: 44100000 | J38: Etat: IRSA à payer
A39: 44300000 | B39: Etat: acomptes IR | C39: =IF(A39=A38,0,SUMIFS(BLG1222!$I:$I,BLG1222!$A:$A,"agricorp",BLG1222!$D:$D,A:A)) -> 0 | D39: 300000 | E39: 150000 | F39: 150000 | I39: 44300000 | J39: Etat: acomptes IR
A40: 44310000 | B40: IR Intermittent Locaux | C40: =IF(A40=A39,0,SUMIFS(BLG1222!$I:$I,BLG1222!$A:$A,"agricorp",BLG1222!$D:$D,A:A)) -> 0 | D40: -200000 | I40: 44310000 | J40: IR Intermittent Locaux
...

Sheet AGRIFARM
J1: 2022 | K1: 2021 | L1: 2020 | M1: 2019
A2: 10100000 | B2: Capital | C2: -3540000000 | E2: -3540000000 | G2: =+VLOOKUP(H2,#REF!,1,FALSE()) -> #VALUE! | H2: 10100000 | I2: Capital | K2: -3540000000 | L2: -3540000000 | M2: -3540000000
A3: 10610000 | B3: Reserves légales | C3: -354000000 | E3: -354000000 | G3: =+VLOOKUP(H3,#REF!,1,FALSE()) -> #VALUE! | H3: 10610000 | I3: Reserves légales | K3: -354000000 | L3: -354000000 | M3: -354000000
A4: 11000000 | B4: RAN Créditeur | C4: -8.509871e+09 | E4: -6.3446446e+09 | G4: =+VLOOKUP(H4,#REF!,1,FALSE()) -> #VALUE! | H4: 11000000 | I4: RAN Créditeur | K4: -9.40908e+09 | L4: -8.509871e+09 | M4: -6.3446446e+09 | N4: -2.1652263e+09
A5: 16100000 | B5: Emprunts BNI | C5: -2000000000 | E5: 0 | G5: =+VLOOKUP(H5,#REF!,1,FALSE()) -> #VALUE! | H5: 16100000 | I5: Emprunts BNI | K5: -3.600927e+09 | L5: -2000000000 | M5: 0
A6: 16120000 | B6: Emprunts BFV | C6: -1.8946752e+09 | E6: -4.0799357e+08 | G6: =+VLOOKUP(H6,#REF!,1,FALSE()) -> #VALUE! | H6: 16120000 | I6: Emprunts BFV | K6: 0 | L6: -1.8946752e+09 | M6: 0
A7: 16130000 | B7: Emprunts BMOI | C7: -2000000000 | G7: =+VLOOKUP(H7,#REF!,1,FALSE()) -> #VALUE! | H7: 16130000 | I7: Emprunts BMOI | K7: 0 | L7: -4000000000 | M7: -4.0799357e+08
A8: 16130000 | B8: Emprunts BMOI MGA | C8: -2000000000 | G8: =+VLOOKUP(H8,#REF!,1,FALSE()) -> #VALUE! | H8: 16200000 | I8: EMPRUNTS BFV | K8: -5.7823688e+08 | M8: -2.2978343e+09
A9: 16884000 | B9: Intérêts couru sur emprunts | C9: -30840097 | E9: 4832320.4 | G9: =+VLOOKUP(H9,#REF!,1,FALSE()) -> #VALUE! | H9: 16400000 | I9: EMPRUNTS BNI | K9: -913586398
A10: 20400000 | B10: Logiciels informatiques & assimilés | C10: 4832320.4 | E10: 617015295 | G10: =+VLOOKUP(H10,#REF!,1,FALSE()) -> #VALUE! | H10: 16430000 | I10: BOA PRET COLLECTIF | K10: -2.3479427e+08
A11: 21100000 | B11: Terrains | C11: 7.3484863e+08 | E11: 4.7259753e+08 | G11: =+VLOOKUP(H11,#REF!,1,FALSE()) -> #VALUE! | H11: 16884000 | I11: Intérêts couru sur emprunts | K11: 0 | L11: -30840097 | M11: -8881771
A12: 21200000 | B12: Agencement amenagement terrain | C12: 1.1032187e+09 | E12: 6.9909811e+09 | G12: =+VLOOKUP(H12,#REF!,1,FALSE()) -> #VALUE! | H12: 20400000 | I12: Logiciels informatiques & assimilés | K12: 4832320.4 | L12: 4832320.4 | M12: 4832320.4
A13: 21300000 | B13: Batiments - Constructions | C13: 8.68729e+09 | E13: 5.397081e+08 | G13: =+VLOOKUP(H13,#REF!,1,FALSE()) -> #VALUE! | H13: 21100000 | I13: Terrains | K13: 1.3115778e+09 | L13: 7.3484863e+08 | M13: 617015295
A14: 21500000 | B14: Agencement aménagement installation | C14: 2.9003776e+08 | E14: 29445569 | G14: =+VLOOKUP(H14,#REF!,1,FALSE()) -> #VALUE! | H14: 21200000 | I14: Agencement amenagement terrain | K14: 1.741202e+09 | L14: 1.1032187e+09 | M14: 4.7259753e+08
A15: 21520000 | B15: INSTALLATION CAMERA | C15: 33571788 | E15: 0 | G15: =+VLOOKUP(H15,#REF!,1,FALSE()) -> #VALUE! | H15: 21300000 | I15: Batiments - Constructions | K15: 9.3963741e+09 | L15: 8.68729e+09 | M15: 6.9909811e+09
A16: 21540000 | B16: MATERIEL ET OUT INDUSTRIEL | C16: 4.169547e+08 | E16: 4.0232754e+09 | G16: =+VLOOKUP(H16,#REF!,1,FALSE()) -> #VALUE! | H16: 21500000 | I16: Agencement aménagement installation | K16: 4.474744e+08 | L16: 2.9003776e+08 | M16: 5.397081e+08
A17: 21540000 | B17: Matériels & outillages | C17: 2.336805e+09 | G17: =+VLOOKUP(H17,#REF!,1,FALSE()) -> #VALUE! | H17: 21520000 | I17: Installations | K17: 33571788 | L17: 33571788 | M17: 29445569
A18: 21540000 | B18: Matériels & outillages TALATA | C18: 1.8188668e+09 | E18: 32942199 | G18: =+VLOOKUP(H18,#REF!,1,FALSE()) -> #VALUE! | H18: 21530000 | I18: Agenc Amenag Batiment | K18: 12600000
A19: 21540000 | B19: MATERIEL DE LABORATOIRE | C19: 2.2047552e+08 | E19: 1.6839917e+09 | G19: =+VLOOKUP(H19,#REF!,1,FALSE()) -> #VALUE! | H19: 21540000 | I19: Matériels & outillages | K19: 8.2536993e+08 | L19: 4.793102e+09 | M19: 4.243751e+09
A20: 21820000 | B20: MMB | C20: 42123956 | E20: 9.6264369e+08 | G20: =+VLOOKUP(H20,#REF!,1,FALSE()) -> #VALUE! | H20: 21810000 | I20: MATÉRIELS & OUTILLAGES | K20: 2.427449e+09
A21: 21820000 | B21: Materiel & mobilier de logement | C21: 14315435 | E21: 2.2047552e+08 | G21: =+VLOOKUP(H21,#REF!,1,FALSE()) -> #VALUE! | H21: 21811000 | I21: Matériels & outillages TALATA | K21: 1.8622359e+09
A22: 21830000 | B22: Materiel de transport | C22: 9.0107832e+08 | E22: 88221560 | G22: =+VLOOKUP(H22,#REF!,1,FALSE()) -> #VALUE! | H22: 21820000 | I22: MMB | K22: 49337398 | L22: 56439391 | M22: 47257634
A23: 21840000 | B23: Matériel informatiques | C23: 95049060 | E23: 0 | G23: =+VLOOKUP(H23,#REF!,1,FALSE()) -> #VALUE! | H23: 21830000 | I23: Materiel de transport | K23: 9.9473781e+08 | L23: 9.0107832e+08 | M23: 9.6264369e+08
A24: 23200000 | B24: Autres immo en cours | C24: 6.7889432e+08 | E24: 0 | G24: =+VLOOKUP(H24,#REF!,1,FALSE()) -> #VALUE! | H24: 21840000 | I24: Matériel informatiques | K24: 1.2353253e+08 | L24: 95049060 | M24: 88221560
A25: 23200000 | B25: Immo en cours dépot | C25: 1.0727673e+09 | E25: 1200000 | G25: =+VLOOKUP(H25,#REF!,1,FALSE()) -> #VALUE! | H25: 21850000 | I25: MATERIEL &MOBILIER DE LOGEMENT | K25: 14315435
A26: 27500000 | B26: Depot & cautionnements verses | C26: 1200000 | E26: -2902076.8 | G26: =+VLOOKUP(H26,#REF!,1,FALSE()) -> #VALUE! | H26: 21860000 | I26: MATERIEL DE LABORATOIRE | K26: 2.3180962e+08
A27: 28040000 | B27: Amts logiciel informatique | C27: -3868540.9 | E27: -1.7227006e+08 | G27: =+VLOOKUP(H27,#REF!,1,FALSE()) -> #VALUE! | H27: 23000000 | I27: IMMO EN COURS | K27: 1.1430707e+09
A28: 28120000 | B28: Amts Agens Amenag Terrain | C28: -2.3839724e+08 | E28: -1.7433025e+09 | G28: =+VLOOKUP(H28,#REF!,1,FALSE()) -> #VALUE! | H28: 23200000 | I28: Autres immo en cours | K28: 1.2284763e+09 | L28: 1.7516616e+09 | M28: 1.6839917e+09
A29: 28130000 | B29: Amts batiments et constructions | C29: -2.1040979e+09 | E29: -2.8957175e+08 | G29: =+VLOOKUP(H29,#REF!,1,FALSE()) -> #VALUE! | H29: 27500000 | I29: Depot & cautionnements verses | K29: 0 | L29: 1200000 | M29: 1200000
A30: 28150000 | B30: Amts agen. amen.instal. | C30: -1.7634706e+08 | E30: -893419.85 | G30: =+VLOOKUP(H30,#REF!,1,FALSE()) -> #VALUE! | H30: 28040000 | I30: Amts logiciel informatique | K30: -4832320.4 | L30: -3868540.9 | M30: -2902076.8
A31: 28152000 | B31: AMORT INSTALLATION CAMERA | C31: -4126812 | E31: 0 | G31: =+VLOOKUP(H31,#REF!,1,FALSE()) -> #VALUE! | H31: 28120000 | I31: Amts Agens Amenag Terrain | K31: -3.6104054e+08 | L31: -2.3839724e+08 | M31: -1.7227006e+08
A32: 28154000 | B32: Amts matériels & outillage | C32: -1.392022e+09 | G32: =+VLOOKUP(H32,#REF!,1,FALSE()) -> #VALUE! | H32: 28130000 | I32: Amts batiments et constructions | K32: -2.5585134e+09 | L32: -2.1040979e+09 | M32: -1.7433025e+09
A33: 28154000 | B33: Amts matériel & outillage TALA | C33: -7.6336681e+08 | E33: -17324137 | G33: =+VLOOKUP(H33,#REF!,1,FALSE()) -> #VALUE! | H33: 28150000 | I33: Amts agen. amen.instal. | K33: -2.1213962e+08 | L33: -1.7634706e+08 | M33: -2.8957175e+08
A34: 28154000 | B34: AMORT MAT LABORATOIRE | C34: -1.1972664e+08 | E34: 1.0228732e+09 | G34: =+VLOOKUP(H34,#REF!,1,FALSE()) -> #VALUE! | H34: 28152000 | I34: AMORT INSTALLATION CAMERA | K34: -7483991 | L34: -4126812 | M34: -893419.85
A35: 28154000 | B35: AMORT SUR MAT ET OUT INDUSTRIEL | C35: -1.7493873e+08 | E35: -1.7496416e+09 | G35: =+VLOOKUP(H35,#REF!,1,FALSE()) -> #VALUE! | H35: 28153000 | I35: Amts Agenc Amenag Batiment | K35: -630000
A36: 28182000 | B36: Amts MMB | C36: -21006458 | E36: -7.6004316e+08 | G36: =+VLOOKUP(H36,#REF!,1,FALSE()) -> #VALUE! | H36: 28154000 | I36: Amts matériels & outillage | K36: -2.3577521e+08 | L36: -2.4500542e+09 | M36: -1.8473207e+09
A37: 28182000 | B37: Amts mat & mob de logt | C37: -11666574 | E37: -97679090 | G37: =+VLOOKUP(H37,#REF!,1,FALSE()) -> #VALUE! | H37: 28181000 | I37: AMTS MATERIELS & OUTILLAGE | K37: -1.6158093e+09
A38: 28183000 | B38: AMT matériel de transport | C38: -7.5423769e+08 | E38: -71476538 | G38: =+VLOOKUP(H38,#REF!,1,FALSE()) -> #VALUE! | H38: 28181100 | I38: Amts matériel & outillage TALA | K38: -9.4692702e+08
A39: 28184000 | B39: Amts materiel informatique | C39: -80279548 | E39: -10324724 | G39: =+VLOOKUP(H39,#REF!,1,FALSE()) -> #VALUE! | H39: 28182000 | I39: Amts MMB | K39: -25650896 | L39: -32673032 | M39: -27648861
A40: 31000000 | B40: Stocks de mat.1ères & fournitures | C40: 1.3578887e+09 | E40: 2.5656028e+09 | G40: =+VLOOKUP(H40,#REF!,1,FALSE()) -> #VALUE! | H40: 28183000 | I40: AMT matériel de transport | K40: -8.2073672e+08 | L40: -7.5423769e+08 | M40: -7.6004316e+08
...

Sheet AGRIVET
D1: 2021 | E1: 2020 | F1: 2019
A2: Compte | B2: Société | C2: Libellé | G2: Compte de gestion | H2: Libellés - groupe
A3: 1010000 | B3: 10100000 | C3: CAPITAL | D3: -4000000000 | E3: -4000000000 | F3: -4000000000 | G3: 10100000 | H3: Capital
A4: 1061000 | B4: 10610000 | C4: RESERVES LÉGALES | D4: -400000000 | E4: -400000000 | F4: -400000000 | G4: 10610000 | H4: Reserves légales
A5: 1062000 | B5: 10620000 | C5: RESERVES FACULTATIVES | D5: -4.5342185e+08 | E5: -4.5342185e+08 | F5: -4.5342185e+08 | G5: 10620000 | H5: RESERVES FACULTATIVES
A6: 1100000 | B6: 11000000 | C6: RAN CREDITEUR | D6: -2.0417021e+10 | E6: -2.0264125e+10 | F6: -9.6521783e+09 | G6: 11000000 | H6: RAN Créditeur
A7: 1200000 | B7: 12000000 | C7: RESULTAT NET BENEFICE | D7: 0 | E7: 0 | F7: 0 | G7: 12000000 | H7: RESULTAT NET BENEFICE
A8: 1280000 | B8: 12800000 | C8: RESULTAT INSTANCE DAFFECTATION | D8: 0 | E8: 0 | F8: -3.7633088e+09 | G8: 12800000 | H8: Résultat en instance d'affectation
A9: 1640000 | B9: 16400000 | C9: EMPRUNTS BNI | D9: -9.135864e+08 | E9: -2000000000 | F9: 0 | G9: 16100000 | H9: Emprunts BNI
A10: 1642000 | B10: 16420000 | C10: Emprunts BMOI MGA | D10: -3.6228689e+09 | E10: -6000000000 | F10: 0 | G10: 16130000 | H10: Emprunts BMOI MGA
A11: 1643000 | B11: 16430000 | C11: BOA PRET COLLECTIF | D11: -3.9734415e+08 | G11: 16430000
A12: 1688500 | B12: 16885000 | C12: Intérêts couru sur emprunts | D12: 0 | E12: -66824742 | F12: 0 | G12: 16884000 | H12: Intérêts couru sur emprunts
A13: 2040000 | B13: 20400000 | C13: LOGICIEL INFO & ASSIMILÉ | D13: 89779560 | E13: 89779560 | F13: 2.6393684e+08 | G13: 20400000 | H13: Logiciels informatiques & assimilés
A14: 2080000 | B14: 20800000 | C14: AUTRES IMMO INCORPORELLES | D14: 11536530 | G14: 20800000
A15: 2120000 | B15: 21200000 | C15: AGENCEMENT AMENAGEMENT TERRAIN | D15: 9054500 | E15: 4654500 | F15: 4654500 | G15: 21200000 | H15: Agencement amenagement terrain
A16: 2130000 | B16: 21300000 | C16: CONSTRUCTIONS | D16: 92084865 | E16: 59268359 | F16: 53086164 | G16: 21300000 | H16: Batiments - Constructions
A17: 2150000 | B17: 21500000 | C17: AGENCEMENT AMENAGEMENT INSTAL | D17: 7.0941593e+08 | E17: 6.8180496e+08 | F17: 6.7257296e+08 | G17: 21500000 | H17: Agencement aménagement
A18: 2153000 | B18: 21530000 | C18: Agenc Amenag Batiment | D18: 0 | E18: 0 | F18: 0 | G18: 21500000 | H18: Agencement aménagement
A19: 2151000 | B19: 21510000 | C19: INSTALLATIONS TELEPHONIQUES | D19: 6314534 | E19: 6314534 | F19: 6314534 | G19: 21520000 | H19: Installations
A20: 2152000 | B20: 21520000 | C20: INSTALLATION CAMERA | D20: 54908530 | E20: 54908530 | F20: 54908530 | G20: 21520000 | H20: Installations
A21: 2181000 | B21: 21810000 | C21: MATÉRIELS & OUTILLAGES | D21: 1.096365e+09 | E21: 1.056192e+09 | F21: 1.0167907e+09 | G21: 21540000 | H21: Matériels & outillages
A22: 2182000 | B22: 21820000 | C22: MMB | D22: 89776925 | E22: 83474134 | F22: 74048092 | G22: 21820000 | H22: MMB
A23: 2185000 | B23: 21850000 | C23: MATERIEL &MOBILIER DE LOGEMENT | D23: 8621314.5 | E23: 8621314.5 | F23: 8621314.5 | G23: 21820000 | H23: MMB
A24: 2186000 | B24: 21860000 | C24: MATERIEL DE LABORATOIRE | D24: 2810305 | E24: 2810305 | F24: 2810305 | G24: 21820000 | H24: MMB
A25: 2187000 | B25: 21870000 | C25: MATERIEL & MOBILIER DE MAGASIN | D25: 10263847 | E25: 10263847 | F25: 10263847 | G25: 21820000 | H25: MMB
A26: 2183000 | B26: 21830000 | C26: MATERIEL DE TRANSPORT | D26: 9.8383174e+08 | E26: 1.0592942e+09 | F26: 9.649424e+08 | G26: 21830000 | H26: Materiel de transport
... A32: 2804000 | B32: 28040000 | C32: AMTS LOGICIEL INFORMATIQUE | D32: -66952203 | E32: -45715393 | F32: -65642767 | G32: 28040000 | H32: Amts logiciel informatique
A33: 2808000 | B33: 28080000 | C33: AMTS AMO INCORPO | D33: -913308.63 | G33: 28080000 | H33: =+C:C -> AMTS AMO INCORPO
A34: 2812000 | B34: 28120000 | C34: AMORT AGENC AMENAG TERRAIN | D34: -2385289.9 | E34: -1917395.4 | F34: -1451945.4 | G34: 28120000 | H34: Amts Agens Amenag Terrain
A35: 2813000 | B35: 28130000 | C35: AMTS CONSTRUCTIONS | D35: -60485037 | E35: -54774933 | F35: -53086164 | G35: 28130000 | H35: Amts batiments et constructions
A36: 2815000 | B36: 28150000 | C36: AMTS AGEN.AMEN.INSTAL. | D36: -4.4697739e+08 | E36: -3.7732355e+08 | F36: -3.0988051e+08 | G36: 28150000 | H36: Amts agen. amen.instal.
A37: 2815100 | B37: 28151000 | C37: AMORT INSTALLATION TELEPHONIQU | D37: -5175941.5 | E37: -4717888.1 | F37: -4259834.7 | G37: 28152000 | H37: AMORT INSTALLATION TELEPHONIQUE & ELECTRIQUE
A38: 2815200 | B38: 28152000 | C38: AMORT INSTALLATION CAMERA | D38: -54908530 | E38: -54908530 | F38: -54908530 | G38: 28152000 | H38: AMORT INSTALLATION TELEPHONIQUE & ELECTRIQUE
A39: 2818100 | B39: 28181000 | C39: AMTS MATERIELS & OUTILLAGE | D39: -5.8247933e+08 | E39: -4.8527236e+08 | F39: -3.8967224e+08 | G39: 28154000 | H39: AMORT SUR MAT ET OUT INDUSTRIEL
A40: 2818200 | B40: 28182000 | C40: AMTS MMB | D40: -46940804 | E40: -40018542 | F40: -33974959 | G40: 28182000 | H40: Amts MMB
A41: 2818400 | B41: 28184000 | C41: AMTS MATERIEL INFORMATIQUE | D41: -1.9541498e+08 | E41: -1.4159418e+08 | F41: -92594943 | G41: 28182000 | H41: Amts MMB
A42: 2818500 | B42: 28185000 | C42: AMTS MAT & MOB DE LOGT | D42: -5691644.9 | E42: -4829513.5 | F42: -3967382 | G42: 28182000 | H42: Amts MMB
A43: 2818700 | B43: 28187000 | C43: AMORT MAT & MOB DE MAGASIN | D43: -10235222 | E43: -10063472 | F43: -9891721.7 | G43: 28182000 | H43: Amts MMB
A44: 2818300 | B44: 28183000 | C44: AMTS MATERIEL DE TRANSPORT | D44: -7.7868285e+08 | E44: -7.9764443e+08 | F44: -7.5399697e+08 | G44: 28183000 | H44: AMT matériel de transport
A45: 2818600 | B45: 28186000 | C45: AMORT MAT LABORATOIRE | D45: -2810305 | E45: -2599532.1 | F45: -2318501.6 | G45: 28184000 | H45: Amts materiel informatique
...

Sheet AGRIVAL
D1: 2021 | E1: 2020 | F1: 2019
A2: Comptes | B2: Société | C2: Libellés | G2: Gestion
A3: 1010000 | B3: 10100000 | C3: CAPITAL | D3: -3980000000 | E3: -3980000000 | F3: -3980000000 | G3: 10100000
A4: 1061000 | B4: 10610000 | C4: RESERVES LÉGALES | D4: -398000000 | E4: -398000000 | F4: -398000000 | G4: 10610000
A5: 1100000 | B5: 11000000 | C5: RAN CREDITEUR | D5: -2.2975565e+10 | E5: -1.6005083e+10 | F5: -7.1772044e+09 | G5: 11000000
A6: 1200000 | B6: 12000000 | C6: RESULTAT NET BENEFICE | D6: 0 | E6: 0 | F6: 0 | G6: 12000000
A7: 1280000 | B7: 12800000 | C7: RESULTAT INSTANCE DAFFECTATION | D7: 0 | E7: 0 | F7: -3.0943388e+09 | G7: 12800000
A8: 1620000 | B8: 16200000 | C8: EMPRUNTS BFV | D8: 0 | E8: 0 | F8: 0 | G8: 16200000
A9: 1642000 | B9: 16420000 | C9: Emprunts BMOI MGA | D9: -5.1787519e+09 | E9: -7.8144285e+09 | F9: -9.4738335e+09 | G9: 16420000
B10: 16500000 | C10: PMT - 1an | D10: -1.6510591e+09 | G10: 16500000
A11: 1688500 | B11: 16885000 | C11: Intérêts couru sur emprunts | D11: 0 | E11: -26496378 | F11: -48392389 | G11: 16885000
A12: 2040000 | B12: 20400000 | C12: LOGICIEL INFO & ASSIMILÉ | D12: 21223664 | E12: 21223664 | F12: 21223664 | G12: 20400000
A13: 2050000 | B13: 20500000 | C13: CONCESSION & DROIT SIMILAIRE | D13: 6174624.8 | E13: 6174624.8 | F13: 6174624.8 | G13: 20500000
A14: 2110000 | B14: 21100000 | C14: TERRAINS | D14: 256800000 | E14: 214200000 | F14: 79000000 | G14: 21100000
A15: 2120000 | B15: 21200000 | C15: AGENCEMENT AMENAGEMENT TERRAIN | D15: 3.3584859e+08 | E15: 3.3584859e+08 | F15: 1.7826659e+08 | G15: 21200000
A16: 2130000 | B16: 21300000 | C16: CONSTRUCTIONS | D16: 1.0186381e+10 | E16: 9.8090212e+09 | F16: 1.0777035e+10 | G16: 21300000
A17: 2150000 | B17: 21500000 | C17: AGENCEMENT AMENAGEMENT INSTAL | D17: 94238265 | E17: 80159882 | F17: 73654882 | G17: 21500000
A18: 2152000 | B18: 21520000 | C18: INSTALLATION CAMERA | D18: 17308000 | E18: 17308000 | F18: 17308000 | G18: 21520000
A19: 2153000 | B19: 21530000 | C19: Agenc Amenag Batiment | D19: 6.0497491e+08 | E19: 4.1427275e+08 | F19: 3.4707275e+08 | G19: 21530000
A20: 2181000 | B20: 21810000 | C20: MATÉRIELS & OUTILLAGES | D20: 1.2516839e+10 | E20: 1.2378615e+10 | F20: 1.125158e+10 | G20: 21810000
A21: 2182000 | B21: 21820000 | C21: MMB | D21: 1.012011e+08 | E21: 84742607 | F21: 66463180 | G21: 21820000
A22: 2183000 | B22: 21830000 | C22: MATERIEL DE TRANSPORT | D22: 4.2199605e+08 | E22: 4.0969674e+08 | F22: 4.4700586e+08 | G22: 21830000
... A63: 4250000 | B63: 42500000 | C63: AVANCES & ACOMPTESAU PERSONNEL | D63: 0 | E63: 0 | F63: 0 | G63: 42500000
B64: 42510000 | C64: Avances quinzaines | D64: 55000 | G64: 42510000
A65: 4252000 | B65: 42520000 | C65: Avances speciales | D65: -176999.85 | E65: -739999.95 | F65: -1.1920929e-09 | G65: 42520000
B66: 42540000 | C66: Tsinjo Fameno | D66: -1107164.2 | G66: 42540000
A67: 4280000 | B67: 42800000 | C67: PERSONNEL CONGES PAYES | D67: -209778785 | E67: -1.2401674e+08 | F67: -1.1148906e+08 | G67: 42800000
A68: 4310000 | B68: 43100000 | C68: CNAPS | D68: -57146780 | E68: -47515147 | F68: -43171089 | G68: 43100000
A69: 4311000 | B69: 43110000 | C69: CNAPS ALLOCAT° FAMILIALES | D69: -1231300 | E69: -1210600 | F69: -1066600 | G69: 43110000
A70: 4320000 | B70: 43200000 | C70: OSTIE | D70: -24279875 | E70: -20363634 | F70: -18501895 | G70: 43200000
B71: 43220000 | C71: FUNHECE | D71: -211602 | G71: 43220000
A72: 4330000 | B72: 43300000 | C72: FMFP | D72: -4072888.8 | E72: -3393939.1 | F72: -3083649.2 | G72: 43300000
A73: 4386000 | B73: 43860000 | C73: ORGANISME-AUTRE CHARGE A PAYER | D73: -19183516 | E73: -33175330 | F73: -32361273 | G73: 43860000
A74: 4400000 | B74: 44000000 | C74: ETAT A PAYER | D74: 0 | E74: 0 | F74: -4.3262382e+08 | G74: 44000000
A75: 4410000 | B75: 44100000 | C75: ETAT: IRSA À PAYER | D75: -31630680 | E75: -28143960 | F75: -23435012 | G75: 44100000
A76: 4430000 | B76: 44300000 | C76: ETAT: ACOMPTES IR | D76: 0 | E76: 6.1614262e+08 | F76: 5.3749559e+08 | G76: 44300000
A77: 4440000 | B77: 44400000 | C77: IR INTERMITENT ETRANGER | D77: 8843961.3 | E77: 9756010.8 | F77: -6244970.6 | G77: 44400000
A78: 4441000 | B78: 44410000 | C78: CREDIT D'IR | D78: 3.4649744e+08 | E78: -1.9073486e-08 | F78: 72648763 | G78: 44410000
A79: 4442000 | B79: 44420000 | C79: IR INTERMITENT LOCAUX | D79: -3880047.4 | E79: -2963305.3 | F79: -2005052.8 | G79: 44420000
A80: 4443000 | B80: 44430000 | C80: IMPOT SUR LES RESULTATS (IR) | D80: 0 | E80: 0 | F80: -6.9195909e+08 | G80: 44430000
...

Sheet SMTP
F1: 2021 | G1: 2020 | H1: EF CONSO 2019 | I1: 2019
F2: =SUBTOTAL(9,F3:F357) -> -0.0014999106 | G2: =SUBTOTAL(9,G3:G195) -> 0.0021070696 | H2: =SUBTOTAL(9,H3:H195) -> 0.00061593644 | I2: =SUBTOTAL(9,I3:I195) -> 0.00061593644 | K2: Compte société | L2: Compte de gestion | M2: Compte société | N2: Libellé | O2: Montant
A3: 1 | B3: 10 | C3: 101 | D3: 10100000 | E3: Capital | F3: -7050000000 | G3: -7050000000 | H3: -7050000000 | I3: -7050000000 | K3: 10100000 | L3: 10100000 | M3: =+VLOOKUP(D3,AGRIVET!$B$3:$G$348,5,FALSE()) -> -4000000000 | N3: Capital | O3: -7050000000
A4: 1 | B4: 10 | C4: 106 | D4: 10610000 | E4: Reserves légales | F4: -705000000 | G4: -705000000 | H4: -705000000 | I4: -705000000 | K4: 10610000 | L4: 10610000 | M4: =+VLOOKUP(D4,AGRIVET!$B$3:$G$348,5,FALSE()) -> -400000000 | N4: Réserve légale | O4: -705000000
A5: 1 | B5: 11 | C5: 110 | D5: 11000000 | E5: RAN Créditeur | F5: -4.9782395e+09 | G5: -4.9782395e+09 | H5: -4.0392523e+09 | I5: -4.0392523e+09 | K5: 11000000 | L5: 11000000 | M5: =+VLOOKUP(D5,AGRIVET!$B$3:$G$348,5,FALSE()) -> -9.6521783e+09 | N5: RAN (solde créditeur) | O5: -4.9782395e+09
A6: 1 | B6: 12 | C6: 128 | D6: 12800000 | E6: Résultat en instance d'affectation | F6: 0 | G6: 0 | H6: -5.4257172e+08 | I6: -5.4257172e+08 | K6: 16412000 | L6: 16100000 | M6: =+VLOOKUP(D6,AGRIVET!$B$3:$G$348,5,FALSE()) -> -3.7633088e+09 | N6: Emprunt BNI | O6: -1000000000
A7: 1 | B7: 16 | C7: 161 | D7: 16100000 | E7: Emprunts BNI | F7: 0 | G7: -1000000000 | H7: 0 | I7: 0 | K7: 16880000 | L7: 16884000 | M7: =+VLOOKUP(D7,AGRIVET!$B$3:$G$348,5,FALSE()) -> #N/A | N7: Intérêts courus | O7: -5448008.9
A8: 1 | B8: 16 | C8: 168 | D8: 16884000 | E8: Intérêts couru sur emprunts | F8: 0 | G8: -19313948 | H8: 0 | I8: 0 | K8: 16884000 | L8: 16884000 | M8: =+VLOOKUP(D8,AGRIVET!$B$3:$G$348,5,FALSE()) -> #N/A | N8: Intérêts courus emprunts | O8: -13865939
A9: 2 | B9: 20 | C9: 204 | D9: 20400000 | E9: Logiciels informatiques & assimilés | F9: 1.6807905e+08 | G9: 1.6807905e+08 | H9: 1.6807905e+08 | I9: 1.6807905e+08 | K9: 20400000 | L9: 20400000 | M9: =+VLOOKUP(D9,AGRIVET!$B$3:$G$348,5,FALSE()) -> 2.6393684e+08 | N9: Logiciels informatiques & assi | O9: 1.6807905e+08
A10: 2 | B10: 21 | C10: 211 | D10: 21100000 | E10: Terrains | F10: 3.9774084e+08 | G10: 3.9774084e+08 | H10: 480198000 | I10: 480198000 | K10: 21100000 | L10: 21100000 | M10: =+VLOOKUP(D10,AGRIVET!$B$3:$G$348,5,FALSE()) -> #N/A | N10: Terrains | O10: 3.9774084e+08
A11: 2 | B11: 21 | C11: 212 | D11: 21200000 | E11: Agencement amenagement terrain | F11: 1.6707008e+08 | G11: 1.5982108e+08 | H11: 1.5982108e+08 | I11: 1.5982108e+08 | K11: 21200000 | L11: 21200000 | M11: =+VLOOKUP(D11,AGRIVET!$B$3:$G$348,5,FALSE()) -> 4654500 | N11: Agenc. et aménag. de terrains | O11: 1.5982108e+08
A12: 2 | B12: 21 | C12: 213 | D12: 21300000 | E12: Batiments - Constructions | F12: 2.4663595e+09 | G12: 2.4663595e+09 | H12: 2.4663595e+09 | I12: 2.4663595e+09 | K12: 21300000 | L12: 21300000 | M12: =+VLOOKUP(D12,AGRIVET!$B$3:$G$348,5,FALSE()) -> 53086164 | N12: Batiments - Constructions | O12: 2.4663595e+09
A13: 2 | B13: 21 | C13: 215 | D13: 21500000 | E13: Agencement aménagement | F13: 4.0890942e+08 | G13: 4.0715942e+08 | H13: 3.8263695e+08 | I13: 3.8263695e+08 | K13: 21500000 | L13: 21500000 | M13: =+VLOOKUP(D13,AGRIVET!$B$3:$G$348,5,FALSE()) -> 6.7257296e+08 | N13: Agencement aménagement install | O13: 4.0715942e+08
A14: 2 | B14: 21 | C14: 215 | D14: 21520000 | E14: Installations | F14: 0 | G14: 41336399 | H14: 41336399 | I14: 41336399 | K14: 21540000 | L14: 21540000 | M14: =+VLOOKUP(D14,AGRIVET!$B$3:$G$348,5,FALSE()) -> 54908530 | N14: Matériel industriel | O14: 5.9350947e+09
... A54: 4 | B54: 44 | C54: 441 | D54: 44100000 | E54: Etat: IRSA à payer | F54: -19337145 | G54: -42455705 | H54: -34221211 | I54: -34221211 | K54: 41300000 | L54: 41310000 | M54: =+VLOOKUP(D54,AGRIVET!$B$3:$G$348,5,FALSE()) -> -37319657 | N54: Clients - Traite reçu | O54: 1.5822673e+08
A55: 4 | B55: 44 | C55: 442 | D55: 44200000 | E55: Etat : IFPB | F55: -9569400 | G55: 0 | H55: -9569400 | I55: -9569400 | M55: =+VLOOKUP(D55,AGRIVET!$B$3:$G$348,5,FALSE()) -> #N/A
A56: 4 | B56: 44 | C56: 443 | D56: 44300000 | E56: Etat : acomptes IR | F56: 113250 | G56: 77134944 | H56: 85089615 | I56: 85089615 | K56: 41600000 | L56: 41600000 | M56: =+VLOOKUP(D56,AGRIVET!$B$3:$G$348,5,FALSE()) -> 1.3739105e+09 | N56: Clients douteux | O56: 5.5257875e+08
A57: 4 | B57: 44 | C57: 444 | D57: 44400000 | E57: Etat à payer | F57: 7425667.3 | G57: -2.6896705e+08 | H57: -62694376 | I57: -62694376 | K57: 41910000 | L57: 41910000 | M57: =+VLOOKUP(D57,AGRIVET!$B$3:$G$348,5,FALSE()) -> 0 | N57: Clients créditeurs : acomptes | O57: -1.0389338e+08
A58: 4 | B58: 44 | C58: 444 | D58: 44410000 | E58: Crédit IR | F58: -2825.2103 | G58: 1.0653845e+08 | H58: 84143209 | I58: 84143209 | K58: 41980000 | L58: 41980000 | M58: =+VLOOKUP(D58,AGRIVET!$B$3:$G$348,5,FALSE()) -> -1.8104082e+09 | N58: Avoir à établir | O58: -16061924
A59: 4 | B59: 44 | C59: 444 | D59: 44411000 | E59: IR Intermittent Locaux | F59: 0 | G59: 195563.04 | H59: -8972079.9 | I59: -8972079.9 | K59: 42110000 | L59: 42110000 | M59: =+VLOOKUP(D59,AGRIVET!$B$3:$G$348,5,FALSE()) -> #N/A | N59: Rémunérations dues personnel | O59: 223804.99
A60: 4 | B60: 44 | C60: 444 | D60: 44412000 | E60: IR INTERMITENT ETRANGER | F60: 0 | G60: 5215228.3 | H60: 110259.78 | I60: 110259.78 | K60: 42120000 | L60: 42110000 | M60: =+VLOOKUP(D60,AGRIVET!$B$3:$G$348,5,FALSE()) -> #N/A | N60: Salaires Temporaires | O60: 809000
A61: 4 | B61: 44 | C61: 445 | D61: 44540000 | E61: TVA à décaisser | F61: -0.079799995 | G61: 7.6293945e-08 | H61: -1.5863031e+08 | I61: -1.5863031e+08 | K61: 42510000 | L61: 42510000 | M61: =+VLOOKUP(D61,AGRIVET!$B$3:$G$348,5,FALSE()) -> -66059083 | N61: Avances quinzaines | O61: 1070000
A62: 4 | B62: 44 | C62: 445 | D62: 44550000 | E62: Credit de taxe | F62: 3.5260939e+08 | G62: 3.6878179e+08 | H62: 0 | I62: 0 | K62: 42520000 | L62: 42520000 | M62: =+VLOOKUP(D62,AGRIVET!$B$3:$G$348,5,FALSE()) -> 0 | N62: Avances spéciales | O62: 31752243
A63: 4 | B63: 44 | C63: 445 | D63: 44561000 | E63: TVA déductibles | F63: 0 | G63: 42039174 | H63: 95132907 | I63: 95132907 | K63: 42530000 | L63: 42520000 | M63: =+VLOOKUP(D63,AGRIVET!$B$3:$G$348,5,FALSE()) -> -6722144 | N63: Avances prêt scolaire | O63: 259999.98
A64: 4 | B64: 44 | C64: 445 | D64: 44571000 | E64: TVA collectée | F64: 60639 | G64: -6.4797105e+08 | H64: -7.3169806e+08 | I64: -7.3169806e+08 | K64: 42800000 | L64: 42800000 | M64: =+VLOOKUP(D64,AGRIVET!$B$3:$G$348,5,FALSE()) -> -11341731 | N64: Congés payés provision | O64: -1.7150059e+08
A65: 4 | B65: 44 | C65: 445 | D65: 44581000 | E65: TVA sur factures non parvenues | F65: 0 | G65: 3.7512559e+08 | H65: 4504385.2 | I65: 4504385.2 | K65: 43100000 | L65: 43100000 | M65: =+VLOOKUP(D65,AGRIVET!$B$3:$G$348,5,FALSE()) -> #N/A | N65: CNaPS | O65: -87785721
A66: 4 | B66: 45 | C66: 451 | D66: 45120000 | E66: AGRIVAL | F66: 0 | G66: 2500000 | H66: 2500000 | I66: 2500000 | K66: 43110000 | L66: 43110000 | M66: =+VLOOKUP(D66,AGRIVET!$B$3:$G$348,5,FALSE()) -> #N/A | N66: Allocation familiale CNAPS | O66: -2641600
A67: 4 | B67: 45 | C67: 455 | D67: 45500000 | E67: Associés compte courant | F67: 2500000 | G67: -4.6420028e+08 | H67: -4.5895406e+08 | I67: -4.5895406e+08 | K67: 43200000 | L67: 43200000 | M67: =+VLOOKUP(D67,AGRIVET!$B$3:$G$348,5,FALSE()) -> 0 | N67: OSTIE | O67: -37622452
... A73: 4 | B73: 46 | C73: 466 | D73: 46613000 | E73: DITE SARLU | F73: 0 | G73: 2031605 | H73: 2031605 | I73: 2031605 | K73: 44410000 | L73: 44411000 | M73: =+VLOOKUP(D73,AGRIVET!$B$3:$G$348,5,FALSE()) -> #N/A | N73: Etat : IR Intermittent | O73: 195563.04
A74: 4 | B74: 46 | C74: 466 | D74: 46614000 | E74: DANIL ISMAEL | F74: 0 | H74: 34521400 | I74: 34521400 | K74: 44420000 | L74: 44412000 | M74: =+VLOOKUP(D74,AGRIVET!$B$3:$G$348,5,FALSE()) -> #N/A | N74: IR Intermittent Etranger | O74: 5215228.3
K75: 44430000 | L75: 44400000 | M75: =+VLOOKUP(D75,AGRIVET!$B$3:$G$348,5,FALSE()) -> #N/A | N75: IR à payer | O75: -2.6896705e+08
A76: 4 | B76: 46 | C76: 466 | D76: 46615000 | E76: EUROPAINTS REFACTURATION | F76: 0 | G76: 2345200 | H76: 32278618 | I76: 32278618 | K76: 44540000 | L76: 44540000 | M76: =+VLOOKUP(D76,AGRIVET!$B$3:$G$348,5,FALSE()) -> #N/A | N76: TVA à décaisser | O76: 7.6293945e-08
A77: 4 | B77: 46 | C77: 466 | D77: 46616000 | E77: FERRIS | F77: 0 | G77: 30667378 | H77: 25197269 | I77: 25197269 | K77: 44550000 | L77: 44550000 | M77: =+VLOOKUP(D77,AGRIVET!$B$3:$G$348,5,FALSE()) -> #N/A | N77: Credit de taxe | O77: 3.6878179e+08
A78: 4 | B78: 46 | C78: 466 | D78: 46617000 | E78: FIRST ENERGY REFACTURATION | F78: 0 | G78: 1.8733868e+08 | H78: 2.4382416e+08 | I78: 2.4382416e+08 | K78: 44560000 | L78: 44561000 | M78: =+VLOOKUP(D78,AGRIVET!$B$3:$G$348,5,FALSE()) -> #N/A | N78: TVA déductibles | O78: -334000
A79: 4 | B79: 46 | C79: 466 | D79: 46618000 | E79: FIRST INVESTISSEMENT | F79: 0 | G79: 1244000 | H79: 1244000 | I79: 1244000 | K79: 44562000 | L79: 44561000 | M79: =+VLOOKUP(D79,AGRIVET!$B$3:$G$348,5,FALSE()) -> #N/A | N79: TVA sur Immobilisation | O79: 1138993.5
A80: 4 | B80: 46 | C80: 466 | D80: 46619000 | E80: FLY TECHNOLOGIE REFACTURATION | F80: 0 | G80: 1.0525247e+08 | H80: 38461774 | I80: 38461774 | K80: 44563000 | L80: 44561000 | M80: =+VLOOKUP(D80,AGRIVET!$B$3:$G$348,5,FALSE()) -> #N/A | N80: TVA Intermittente Déductible | O80: 3039959
A81: 4 | B81: 46 | C81: 466 | D81: 46620000 | E81: AGRIFEED REFACTURATION | F81: 0 | G81: 1220031.3 | H81: 487556 | I81: 487556 | K81: 44564000 | L81: 44561000 | M81: =+VLOOKUP(D81,AGRIVET!$B$3:$G$348,5,FALSE()) -> 0 | N81: TVA pour les Services | O81: 38500346
A82: 4 | B82: 46 | C82: 466 | D82: 46621000 | E82: IDF REFACTURATION | F82: 0 | G82: 96224546 | H82: 1.3425194e+08 | I82: 1.3425194e+08 | K82: 44565000 | L82: 44561000 | M82: =+VLOOKUP(D82,AGRIVET!$B$3:$G$348,5,FALSE()) -> #N/A | N82: TVA pour les Biens | O82: -306124.47
A83: 4 | B83: 46 | C83: 466 | D83: 46622000 | E83: ID MOTORS REFACTURATION | F83: 0 | G83: 2.6239274e+08 | H83: 2.0363628e+08 | I83: 2.0363628e+08 | K83: 44570000 | L83: 44571000 | M83: =+VLOOKUP(D83,AGRIVET!$B$3:$G$348,5,FALSE()) -> #N/A | N83: TVA collectées | O83: -3.5407218e+08
A84: 4 | B84: 46 | C84: 466 | D84: 46623000 | E84: ID RENTAL REFACTURATION | F84: 0 | G84: 20625566 | H84: 3903421.9 | I84: 3903421.9 | K84: 44571000 | L84: 44571000 | M84: =+VLOOKUP(D84,AGRIVET!$B$3:$G$348,5,FALSE()) -> #N/A | N84: TVA Intermitente étranger | O84: -3039959
...

Sheet AGRIKOBA
A2: Num.compte | C2: Libellés | D2: 2021 | E2: 2020 | F2: 2019 | G2: Gestion
A3: 1010000 | B3: 10100000 | C3: CAPITAL | D3: -1200000000 | E3: -100000000 | F3: -100000000 | G3: 10100000 | H3: CAPITAL
A4: 1190000 | B4: 11900000 | C4: RAN DEBITEUR | D4: 1.6552003e+09 | E4: 1.6552003e+09 | F4: 5.7469412e+08 | G4: 11900000 | H4: RAN DEBITEUR
A5: 1200000 | B5: 12000000 | C5: RESULTAT NET BENEFICE | D5: 0 | F5: 0 | G5: 12000000 | H5: RESULTAT NET BENEFICE
B6: 12900000 | C6: RESULTAT NET PERTE | D6: 1.4736448e+09 | G6: 12900000 | H6: RESULTAT NET PERTE
A7: 1630000 | B7: 16300000 | C7: EMPRUNT BGFI | D7: 0 | F7: -2.6502224e+09 | G7: 16300000 | H7: EMPRUNT BGFI
A8: 1631000 | B8: 16310000 | C8: Emprunts BNI 746 MGA | D8: 0 | F8: -4.5505451e+08 | G8: 16310000 | H8: Emprunts BNI 746 MGA
A9: 1640000 | B9: 16400000 | C9: EMPRUNTS BNI | D9: -1.5957046e+09 | E9: -2.3202105e+09 | F9: 0 | G9: 16400000 | H9: EMPRUNTS BNI
A10: 1641000 | B10: 16410000 | C10: Emprunts BNI 746 MGA | D10: -3.2193458e+08 | E10: -4.1338519e+08 | F10: 0 | G10: 16410000 | H10: Emprunts BNI 746 MGA
A11: 2110000 | B11: 21100000 | C11: TERRAINS | D11: 55348271 | E11: 66666667 | F11: 0 | G11: 21100000 | H11: TERRAINS
A12: 2120000 | B12: 21200000 | C12: AGENCEMENT AMENAGEMENT TERRAIN | D12: 144235358 | E12: 110417775 | F12: 90218000 | G12: 21200000 | H12: AGENCEMENT AMENAGEMENT TERRAIN
A13: 2130000 | B13: 21300000 | C13: CONSTRUCTIONS | D13: 2.7686945e+09 | E13: 2.7686945e+09 | F13: 1.2789215e+09 | G13: 21300000 | H13: CONSTRUCTIONS
A14: 2150000 | B14: 21500000 | C14: AGENCEMENT AMENAGEMENT INSTAL | D14: 1.2591835e+09 | E14: 1.2591835e+09 | F14: 1.2647545e+09 | G14: 21500000 | H14: AGENCEMENT AMENAGEMENT INSTAL
A15: 2155000 | B15: 21550000 | C15: MACHINES INDUSTRIELS | D15: 4.5303871e+09 | E15: 4.5303871e+09 | F15: 4.3400617e+09 | G15: 21550000 | H15: MACHINES INDUSTRIELS
A16: 2181000 | B16: 21810000 | C16: MATÉRIELS & OUTILLAGES | D16: 1.5843821e+08 | E16: 1.556157e+08 | F16: 1.5516622e+08 | G16: 21810000 | H16: MATÉRIELS & OUTILLAGES
A17: 2182000 | B17: 21820000 | C17: MMB | D17: 19117907 | E17: 14310573 | F17: 8909239.9 | G17: 21820000 | H17: MMB
B18: 21830000 | C18: MATERIEL DE TRANSPORT | D18: 9141666.7 | G18: 21830000 | H18: MATERIEL DE TRANSPORT
A19: 2184000 | B19: 21840000 | C19: MATÉRIEL INFORMATIQUES | D19: 41118647 | E19: 40168647 | F19: 35759247 | G19: 21840000 | H19: MATÉRIEL INFORMATIQUES
B20: 21850000 | C20: MATERIEL &MOBILIER DE LOGEMENT | D20: 4304797.1 | G20: 21850000 | H20: MATERIEL &MOBILIER DE LOGEMENT
A21: 2300000 | B21: 23000000 | C21: IMMO EN COURS | D21: 70057746 | E21: 0 | F21: 1.6314104e+09 | G21: 23000000 | H21: IMMO EN COURS
A22: 2750000 | B22: 27500000 | C22: DEPOT & CAUTIONNEMENTS VERSES | D22: 0 | E22: 16380000 | F22: 1000000 | G22: 27500000 | H22: DEPOT & CAUTIONNEMENTS VERSES
A23: 2812000 | B23: 28120000 | C23: AMORT AGENC AMENAG TERRAIN | D23: -13385195 | E23: -6807507 | F23: -2751444.7 | G23: 28120000 | H23: AMORT AGENC AMENAG TERRAIN
A24: 2813000 | B24: 28130000 | C24: AMTS CONSTRUCTIONS | D24: -2.885326e+08 | E24: -1.5009787e+08 | F24: -67115811 | G24: 28130000 | H24: AMTS CONSTRUCTIONS
A25: 2815000 | B25: 28150000 | C25: AMTS AGEN.AMEN.INSTAL. | D25: -3.8243224e+08 | E25: -2.5651389e+08 | F25: -1.3059555e+08 | G25: 28150000 | H25: AMTS AGEN.AMEN.INSTAL.
A26: 2815500 | B26: 28155000 | C26: AMORT MACHINES INDUSTRIELS | D26: -1.6770622e+09 | E26: -1.2240235e+09 | F26: -7.7860667e+08 | G26: 28155000 | H26: AMORT MACHINES INDUSTRIELS
A27: 2818100 | B27: 28181000 | C27: AMTS MATERIELS & OUTILLAGE | D27: -49734127 | E27: -33955047 | F27: -18396598 | G27: 28181000 | H27: AMTS MATERIELS & OUTILLAGE
A28: 2818200 | B28: 28182000 | C28: AMTS MMB | D28: -3753112.8 | E28: -2185819.5 | F28: -1098080.7 | G28: 28182000 | H28: AMTS MMB
B29: 28183000 | C29: AMTS MATERIEL DE TRANSPORT | D29: -1352204.9 | G29: 28183000 | H29: AMTS MATERIEL DE TRANSPORT
A30: 2818400 | B30: 28184000 | C30: AMTS MATERIEL INFORMATIQUE | D30: -28962544 | E30: -18859028 | F30: -9491036.6 | G30: 28184000 | H30: AMTS MATERIEL INFORMATIQUE
A31: 3100000 | B31: 31000000 | C31: STOCKS DE MAT.1ERES&FOURNITURE | D31: 3.7838989e+08 | E31: 1.5995822e+09 | F31: =136327860+17157114 -> 153484974 | G31: 31000000 | H31: STOCKS DE MAT.1ERES&FOURNITURE
A32: 3110000 | B32: 31100000 | C32: STOCKS DES EMBALLAGES | D32: 24830517 | E32: 24830517 | G32: 31100000 | H32: STOCKS DES EMBALLAGES
A33: 3550000 | B33: 35500000 | C33: STOCKS PRODUITS FINIS | D33: 1.0349128e+09 | E33: 79263118 | F33: 402920473 | G33: 35500000 | H33: STOCKS PRODUITS FINIS
A34: 4011000 | B34: 40110000 | C34: FOURNISSEURS LOCAUX | D34: -1.8351709e+09 | E34: -3.6914243e+09 | F34: -2.6321989e+09 | G34: 40110000 | H34: FOURNISSEURS LOCAUX
A35: 4012000 | B35: 40120000 | C35: FOURNISSEURS ETRANGERS | D35: 3021304.2 | E35: 0 | F35: -714572190 | G35: 40120000 | H35: FOURNISSEURS ETRANGERS
A36: 4034000 | B36: 40340000 | C36: F/SSEURS EFFETS À PAYER BNI | D36: -1.0174928e+08 | E36: -63121776 | F36: -23326387 | G36: 40340000 | H36: F/SSEURS EFFETS À PAYER BNI
A37: 4040000 | B37: 40400000 | C37: F/SSEURS D'IMMOBILISATIONS | D37: 0 | E37: 0 | F37: -6.656958e+08 | G37: 40400000 | H37: F/SSEURS D'IMMOBILISATIONS
A38: 4081000 | B38: 40810000 | C38: F/SSEURS LOC FACT À RECEVOIR | D38: -1.3244481e+08 | E38: -64753104 | F38: -1.0857839e+08 | G38: 40810000 | H38: F/SSEURS LOC FACT À RECEVOIR
B39: 40820000 | C39: F/SSEURS ETR FACT À RECEVOIR | D39: 0 | G39: 40820000 | H39: F/SSEURS ETR FACT À RECEVOIR
A40: 4091000 | B40: 40910000 | C40: FRNS LOCAUX DEBITEURS:AVANCE | D40: 134109583 | E40: 83376330 | F40: 43790926 | G40: 40910000 | H40: FRNS LOCAUX DEBITEURS:AVANCE
A41: 4092000 | B41: 40920000 | C41: FRNS ETRANGER DEBITEUR:AVANCE | D41: 4593682.3 | E41: 39380553 | F41: 0 | G41: 40920000 | H41: FRNS ETRANGER DEBITEUR:AVANCE
...

Sheet LMOI
E2: -1.0490417e-05
B3: Libellés | C3: 2021 | D3: 2020 | E3: 2019 | F3: Gestion
A4: 10100000 | B4: Capital | C4: -2500000000 | D4: -2500000000 | E4: -10000000 | F4: 10100000
A5: 10500000 | B5: Ecart d'évalutations | C5: -4.8681626e+09 | D5: -4.8681626e+09 | E5: 0 | F5: 10500000
A6: 11900000 | B6: RAN débiteur | C6: 44761038 | D6: 26908969 | E6: 26908969 | F6: 11900000
A7: 12800000 | B7: Resultat net en instance d'affectat | C7: 0 | D7: -22734534 | E7: 17852069 | F7: 12800000
A8: 12900000 | B8: Resultat net de exercice perte | C8: 0 | D8: 17852069 | E8: 0 | F8: 12900000
A9: 16100000 | B9: Emprunts BMOI | C9: -7.7871447e+09 | D9: -8.1756144e+09 | E9: -17895000000 | F9: 16100000
A10: 16110000 | B10: EMPRUNTS RABOBANK | C10: -1.1175588e+10 | D10: -1.79418e+10 | E10: -2.3208642e+10 | F10: 16110000
A11: 16200000 | B11: Emprunts BNI | C11: -5.7608547e+09 | D11: -8.1153054e+09 | E11: -9895000000 | F11: 16200000
A12: 16411000 | B12: DETTE COURT TERME BMOI | C12: -388469700 | D12: -2.1674402e+09 | E12: 0 | F12: 16411000
A13: 16413000 | B13: DETTE COURT TERME BNI | C13: -1.9429275e+09 | D13: -1.756342e+09 | E13: 0 | F13: 16413000
A14: 16414000 | B14: DETTE A COURT TERME BNI 2 | C14: -4.115232e+08 | D14: -3.7251592e+08 | E14: 0 | F14: 16413000
A15: 16420000 | B15: A RENOMMER | C15: 0 | D15: -5.9806e+09 | E15: 0 | F15: 16420000
... A67: 28120000 | B67: Amts Agens Amenag Terrain | C67: -5.8940399e+08 | D67: -2.7163079e+08 | E67: -67302147 | F67: 28120000
A68: 28121000 | C68: 0 | E68: -33493017 | F68: 28120000
A69: 28131000 | B69: AMMOT ABRI VOITURE | C69: -1329490.8 | D69: -1329490.8 | E69: 0 | F69: 28131000
A70: 28132000 | B70: AMMORT SILO | C70: 0 | D70: 0 | E70: 0 | F70: 28131000
A71: 281321000 | B71: AMMORT SOCLE SILO | C71: 0 | D71: -3.1303259e+08 | E71: 0 | F71: 28131000
A72: 28132300 | B72: AMMORT SILO 400T | C72: -28006521 | D72: -28006521 | E72: 0 | F72: 28131000
A73: 28132400 | B73: AMMORT SOUS SOL | C73: -70816839 | D73: -70816839 | E73: 0 | F73: 28131000
A74: 28133000 | B74: AMMORT TOUR ET SILO | C74: 0 | D74: 0 | E74: 0 | F74: 28131000
A75: 281331 | B75: AMMORT TOUR 1-2 RDC | C75: 0 | D75: -27982948 | E75: 0 | F75: 28131000
A76: 28133200 | B76: AMMORT TOUR 1-2 1ER ETAGE | C76: -27982948 | D76: -27982948 | E76: 0 | F76: 28131000
A77: 28133300 | B77: AMMORT TOUR 1-2 2EME ETAGE | C77: -27982948 | D77: -27982948 | E77: 0 | F77: 28131000
A78: 28133400 | B78: AMMORT TOUR 1-2 3EME ETAGE | C78: -27982948 | D78: -27982948 | E78: 0 | F78: 28131000
A79: 28133500 | B79: AMMORT TOUR 1-2 4EME ETAGE | C79: -27982948 | D79: -27982948 | E79: 0 | F79: 28131000
A80: 28133600 | B80: AMMORT TOUR 1-2 5EME ETAGE | C80: -27982948 | D80: -27982948 | E80: 0 | F80: 28131000
... A107: 35503000 | B107: STOCK SON | C107: 1.600163e+09 | D107: 1896469666 | E107: 0 | F107: 31000000
A108: 38000000 | B108: Stocks flottants | C108: 0 | E108: 2.3276736e+10 | F108: 38000000
A109: 39200000 | B109: PERTE DE STOCK MP | C109: 0 | D109: -5.3265475e+08 | E109: 0 | F109: 39200000
A110: 39500000 | B110: PERTE DE STOCK PF | C110: -66200000 | D110: -66200000 | E110: 0 | F110: 39500000
A111: 40110000 | B111: Fournisseur locaux | C111: -3.5059014e+09 | D111: -3.0687213e+09 | E111: -1.2251704e+09 | F111: 40110000
A112: 40120000 | B112: Fournisseur étranger | C112: -5.3375427e+10 | D112: -3.094073e+10 | E112: -3.4974505e+10 | F112: 40120000
A113: 40300000 | B113: F/sseurs effets à payer BMOI | C113: 0 | D113: 66129851 | E113: -1.5066803e+09 | F113: 40300000
A114: 40310000 | B114: F/sseurs effets à payer BNI | C114: 209236.39 | D114: -3.3100691e+08 | E114: -86343636 | F114: 40310000
A115: 40400000 | B115: F/sseurs d'immobilisations | C115: -9.4749057e+09 | D115: -1.0157799e+10 | E115: -5.7863478e+09 | F115: 40400000
A116: 40800000 | B116: F/sseurs fact à recevoir | C116: -2840834.2 | D116: -2832082.2 | E116: -99747596 | F116: 40800000
A117: 40810000 | B117: FRNS FACT NON PARVENUES | C117: 0 | D117: 0 | E117: -4218536.5 | F117: 40810000
A118: 40910000 | B118: Frns débiteurs: avances et acomptes | C118: 5.9587328e+08 | D118: 2.0113481e+10 | E118: 6.3668004e+08 | F118: 40910000
...

Sheet TARTINE
F2: EF CONSO
C3: Libellés | D3: 2021 | E3: 2020 | F3: 2019 | G3: Gestion
A4: 101000 | B4: 10100000 | C4: CAPITAL SOCIAL | D4: -10000000 | E4: -10000000 | F4: -10000000 | G4: 10100000
A5: 110000 | B5: 11000000 | C5: REPPORT | D5: -1.6673122e+08 | E5: -1.6673122e+08 | F5: -1.6673122e+08 | G5: 11000000
A6: 120000 | B6: 12000000 | C6: RESULTAT EN INSTANCE | D6: -5.5200068e+08 | E6: -1.8951649e+08 | F6: 0 | G6: 12000000
B7: 12800000 | C7: RESULTAT EN INSTANCE D AFFECTATION | D7: 0 | F7: 1.1298661e+08 | G7: 12800000
A8: 164000 | B8: 16400000 | C8: EMPRUNT A LMT | D8: 92.52 | E8: 92.52 | F8: 0 | G8: 16100000
A9: 203000 | B9: 20300000 | C9: FRAIS DE PREMIER ETABLISSEMENT | D9: 395000 | E9: 395000 | F9: 395000 | G9: 20300000
B10: 21300000 | C10: CONSTRUCTION | D10: 4.134719e+08 | G10: 21500000
A11: 215000 | B11: 21500000 | C11: AGENCEMENT,AMENAGEMENT BATIMENT | D11: 33185707 | E11: 33185707 | F11: 33185707 | G11: 21500000
A12: 215400 | B12: 21540000 | C12: MATERIET ET OUTILLAGE INDUSTRIEL | D12: 4.6715389e+09 | E12: 4.4693722e+09 | F12: 3.9804631e+09 | G12: 21540000
A13: 218200 | B13: 21820000 | C13: MATERIEL DE TRANSPORT | D13: 6.8631579e+08 | E13: 6.3631579e+08 | F13: 3.2772076e+08 | G13: 21830000
A14: 218300 | B14: 21830000 | C14: MATERIELT ET MOBILIER DE BUREAU | D14: 3.2970518e+08 | E14: 3.2970518e+08 | F14: 6.3344079e+08 | G14: 21820000
A15: 218310 | B15: 21831000 | C15: MATERIEL INFORMATIQUE &DIVERS MACHI | D15: 2.7503161e+08 | E15: 2.6173275e+08 | F15: 257013902 | G15: 21840000
A16: 232000 | B16: 23200000 | C16: IMMOBILISATION EN COURS | D16: 0 | E16: 2.5597773e+08 | F16: 2.5597773e+08 | G16: 23200000
A17: 275000 | B17: 27500000 | C17: DEPOT ET CAUTIONNEMENT VERSE | D17: 7776400 | E17: 7776400 | F17: 7764400 | G17: 27500000
A18: 280300 | B18: 28030000 | C18: AMORTISSEMENT FRAIS D'ETABLISSEMENT | D18: -395000 | E18: -395000 | F18: -395000 | G18: 28030000
B19: 28130000 | C19: AMORTISSEMENT CONSTRUCTIONS | D19: -33967322 | G19: 28150000
A20: 281500 | B20: 28150000 | C20: AMORTISSEMENT AGENCEMENT AMENAGM | D20: -25367332 | E20: -22048761 | F20: -18730191 | G20: 28150000
A21: 281540 | B21: 28154000 | C21: AMORTISSEMENT MAT ET OUTILLAGE | D21: -3.4536574e+09 | E21: -2.9932424e+09 | F21: -2.9932424e+09 | G21: 28154000
A22: 281550 | B22: 28155000 | C22: AMORTISSEMENT GROUPE, MATERIELS | D22: -4.1078548e+08 | E22: -4.1078548e+08 | F22: 0 | G22: 28154000
A23: 281820 | B23: 28182000 | C23: AMORTISSEMENT MATERIEL DE TRANSPORT | D23: -5.7857341e+08 | E23: -4.7974115e+08 | F23: -3.8053146e+08 | G23: 28183000
A24: 281830 | B24: 28183000 | C24: AMORTISSEMENT MOBILIER DE BUREAU | D24: -3.2654307e+08 | E24: -3.2430448e+08 | F24: -3.2207525e+08 | G24: 28182000
A25: 281831 | B25: 28183100 | C25: AMORTISSEMENT MAT INFORMATIQUE | D25: -2.580737e+08 | E25: -2.4785202e+08 | F25: -222111311 | G25: 28184000
A26: 310000 | B26: 31000000 | C26: STOCK | D26: 3769834243 | E26: 2913947581 | F26: 2.6087187e+09 | G26: 31000000
A27: 350000 | B27: 35000000 | C27: STOCK PRODUIT FINI | D27: 54663892 | E27: -1292000 | F27: 63711112 | G27: 35500000
A28: 401000 | B28: 40100000 | C28: FOURNISSEUR D'EXPLOITATION | D28: -1.3561763e+09 | E28: -4.8513681e+08 | F28: 0 | G28: 40110000
A29: 401100 | B29: 40110000 | C29: FOURNISSEUR ETRANGER | D29: 45300075 | E29: 86420751 | F29: -4.0179266e+08 | G29: 40110000
A30: 404000 | B30: 40400000 | C30: FOURNISSEUR D'IMMOBILISATION | D30: -9049257.6 | E30: -7849257.6 | F30: -7849257.6 | G30: 40400000
A31: 411000 | B31: 41100000 | C31: CLIENT | D31: 4.1121022e+08 | E31: 4.2339562e+08 | F31: 4.175079e+08 | G31: 41100000
... A70: 606211 | B70: 60621100 | C70: HUILE, CARBURANT, GRAISSE POUR BOUL | D70: 6.7169799e+08 | E70: 3.9791267e+08 | F70: 0 | G70: 60600000
B71: 60630000 | C71: GAS OIL POUR GROUPE ELECTROGENE | D71: 10625000 | G71: 60600000
A72: 606400 | B72: 60640000 | C72: FOURNITURES ADMINISTRATIVES | D72: 12582915 | E72: 5564142 | F72: 5126524.3 | G72: 60600000
B73: 60812000 | C73: Gasy Net | D73: 0 | F73: 360794 | G73: 60800000
B74: 61000000 | C74: FRAIS DIVERS | D74: 6660426.3 | G74: 60600000
B75: 61100000 | C75: sous traitances | D75: 0 | F75: 23169247 | G75: 61100000
A76: 611400 | B76: 61140000 | C76: VISITE | D76: 0 | E76: 1884396 | F76: 0 | G76: 61100000
A77: 611620 | B77: 61162000 | C77: DSMI | D77: 0 | E77: 3765640.3 | F77: 0 | G77: 61100000
A78: 613000 | B78: 61300000 | C78: LOCATION D' IMMEUBLE | D78: 1200000 | E78: 1200000 | F78: 1800000 | G78: 61300000
B79: 61300100 | C79: LOCATION BOUTEILLE A GAZ | D79: 1328416.7 | G79: 61300000
...

Sheet IDF
C1: 2021 | D1: 2020
A2: 10100000 | B2: Capital | C2: -4520000000 | D2: -4520000000 | E2: -4520000000 | F2: 10100000 | H2: -4520000000
A3: 10610000 | B3: Reserves légales | C3: -452000000 | D3: -452000000 | E3: -452000000 | F3: 10610000 | H3: -452000000
A4: 11000000 | B4: RAN crediteur | C4: -5.3453872e+09 | D4: -5.3453872e+09 | E4: -5.3453872e+09 | F4: 11000000 | H4: -5.3453872e+09
A5: 12000000 | B5: Resultat net de l'exercice benefice | C5: 0 | D5: 0 | E5: 0 | F5: 12000000 | H5: 0
A6: 12800000 | B6: Resultat net en instance d'affectat | C6: -3.7114218e+09 | D6: -2.6345924e+09 | E6: -1.2928444e+09 | F6: 12800000 | H6: -1.2928444e+09
A7: 16200000 | B7: Emprunts LMT BNI | C7: -2.0159906e+08 | D7: -9.6428724e+08 | E7: -1.9781291e+09 | F7: 16100000 | H7: -1.9781291e+09
A8: 16210000 | B8: Emprunt CTS BNI | C8: 0 | D8: -500000000 | E8: 0 | F8: 16100000 | H8: 0
A9: 16220000 | B9: Emprunt part -1an BGFI | C9: -7.2024501e+08 | D9: -6.5107759e+08 | E9: 0 | F9: 16150000 | H9: 0
A10: 16230000 | B10: Emprunt part -1an BNI | C10: -9.9179637e+08 | D10: -6.9727864e+08 | E10: 0 | F10: 16100000 | H10: 0
A11: 16450000 | B11: EMPRUNT BGFI | C11: -3.8836305e+08 | D11: -1.1086081e+09 | E11: -2.1570666e+09 | F11: 16150000 | H11: -2.1570666e+09
A12: 16500000 | B12: Depots et cautionnements re | C12: -1.5811715e+08 | D12: -1.5621e+08 | E12: -2.2623315e+08 | F12: 16500000 | H12: -2.2623315e+08
A13: 16510000 | B13: Caution la CITY | C13: -7.4047613e+08 | D13: -6.2032379e+08 | E13: -4.4018188e+08 | F13: 16500000 | H13: -4.4018188e+08
... A54: 41910000 | B54: Clients créditeurs: acomptes | C54: -1.2180264e+09 | D54: -67001176 | E54: -38719439 | F54: 41910000 | H54: -38719439
A55: 41980000 | C55: 0 | E55: -39797548 | F55: 41980000 | H55: -39797548
A56: 42100000 | B56: Rémunérations dues au personnel | C56: 7026192.6 | D56: -1976146.9 | E56: 0 | F56: 42110000 | H56: 0
A57: 42110000 | B57: Salaires Temporaires | C57: 0 | D57: 0 | E57: 0 | F57: 42110000 | H57: 0
A58: 42520000 | B58: Avances spéciales | C58: -21667.66 | D58: 1325000 | E58: 0 | F58: 42520000 | H58: 0
A59: 42800000 | B59: Congés payés provision | C59: -73922784 | D59: -42239582 | E59: -45822526 | F59: 42800000 | H59: -45822526
A60: 43100000 | B60: CNaPS | C60: -12983942 | D60: -17967253 | E60: -14381402 | F60: 43100000 | H60: -14381402
A61: 43110000 | B61: Allocation familiale CNAPS | C61: -804000 | D61: -396000 | E61: =-240000 -> -240000 | F61: 43110000 | H61: -240000
A62: 43200000 | B62: OSTIE | C62: -7795343.8 | D62: -7652251.4 | E62: =-6115457.94+H63 -> -6163457.9 | F62: 43200000 | H62: -6115457.9
A63: 43220000 | B63: FUNECHE | C63: -17000 | D63: -40000 | F63: 43100000 | H63: -48000
A64: 43300000 | B64: FMFP | C64: -254669.08 | D64: -1283375.2 | E64: -1027243 | F64: 43300000 | H64: -1027243
A65: 43860000 | B65: Organismes autres charges à payer | C65: 0 | D65: -4531293 | E65: -13662186 | F65: 43860000 | H65: -13662186
A66: 44000000 | B66: Etat à payer | C66: 0 | D66: 0 | E66: 0 | F66: 44400000 | H66: 0
A67: 44100000 | B67: Etat: IRSA à payer | C67: -18328370 | D67: -18295478 | E67: -12151263 | F67: 44100000 | H67: -12151263
A68: 44200000 | B68: Etat : IFPB | C68: -898979230 | D68: -452291346 | E68: -335608089 | F68: 44200000 | H68: -335608089
A69: 44300000 | B69: Etat: acomptes IR | C69: 3.3738727e+08 | D69: 3.4314863e+08 | E69: 4.2736981e+08 | F69: 44300000 | H69: 4.2736981e+08
A70: 44400000 | B70: Crédit IR | C70: 1.1982909e+08 | D70: 70987822 | E70: 2545460.2 | F70: 44410000 | H70: 2545460.2
A71: 44410000 | B71: IR Intermittent locaux | C71: -2186426.3 | D71: -2168421.1 | E71: -394354.33 | F71: 44411000 | H71: -394354.33
A72: 44420000 | B72: TVA Intermittente étranger | C72: 2078209.2 | D72: 1531605.2 | E72: -8715235.3 | F72: 44412000 | H72: -8715235.3
A73: 44430000 | B73: Impôts sur les résultats (IR) | C73: 0 | D73: -2.9430691e+08 | E73: -3.5892745e+08 | F73: 44400000 | H73: -3.5892745e+08
A74: 44540000 | B74: TVA à décaisser | C74: -1.0492892e+08 | D74: 0 | E74: -1.5175573e+08 | F74: 44540000 | H74: -1.5175573e+08
A75: 44550000 | B75: Credit de taxe | C75: 0 | D75: 13647300 | E75: 0 | F75: 44550000 | H75: 0
... A102: 46720800 | B102: AGRIFARM | C102: 0 | D102: -187680 | E102: -211500 | F102: 46610000 | H102: -211500
A103: 46721000 | B103: SIRR | C103: 0 | D103: 0 | E103: 0 | F103: #N/A | H103: 0
A104: 46722000 | B104: SIM | C104: 0 | D104: 395000000 | E104: 695000000 | F104: 46731000 | H104: 695000000
A105: 46723000 | B105: AMCHO | C105: 0 | D105: 0 | E105: 500000000 | F105: 46732000 | H105: 500000000
A106: 46724000 | B106: FLY TECHNOLOGIE | C106: 0 | D106: -48344709 | E106: 42131026 | F106: 46733000 | H106: 42131026
...

Sheet RYA
D1: 2021 | E1: 2020 | F1: 2019
A2: N°COMPTE | C2: LIBELLE
A3: 101000 | B3: 10100000 | C3: Capital | D3: -1350000000 | E3: -1100000000 | F3: -10000000 | G3: 10100000
A4: 119000 | B4: 11900000 | C4: RAN (Solde débiteur) | D4: 1.8101098e+08 | E4: 1.8101098e+08 | F4: 1.1150155e+08 | G4: 11900000
A5: 120000 | B5: 12000000 | C5: Résultat - bénéfice | D5: -3.4222507e+08 | E5: 0 | F5: 0 | G5: 12000000
A6: 129000 | B6: 12900000 | C6: Résultat - perte | D6: 0 | E6: 0 | F6: 0 | G6: 12900000
B7: 16413000 | C7: Emprunt BFV_Part plus d'un an | D7: -3.6228585e+09 | G7: 16413000
B8: 16413100 | C8: Emprunt BFV-Part moins d'un an | D8: -6.2936178e+08 | G8: 16413000
A9: 165000 | B9: 16500000 | C9: Depots et cautionnements reçus | D9: -64226195 | E9: -44340784 | F9: 0 | G9: 16500000
A10: 211000 | B10: 21100000 | C10: Terrains | D10: 1.0381894e+09 | E10: 9.1318939e+08 | F10: 7.9407939e+08 | G10: 21100000
A11: 212000 | B11: 21200000 | C11: Agenc. et aménag. de terrains | D11: 1.7683271e+08 | E11: 1.7683271e+08 | F11: 1.8290495e+08 | G11: 21200000
A12: 213000 | B12: 21300000 | C12: Batiments - Constructions | D12: 5.2059049e+09 | E12: 4.4697993e+08 | F12: 4.4697993e+08 | G12: 21300000
A13: 215000 | B13: 21500000 | C13: Agencement aménagement install | D13: 1.1546931e+08 | E13: 63528991 | F13: 46270341 | G13: 21500000
A14: 218100 | B14: 21810000 | C14: Matériels & outillages | D14: 8498717.8 | E14: 3613750 | F14: 3613750 | G14: 21540000
A15: 218800 | B15: 21880000 | C15: Materiel&mobilier de logement | D15: 77100928 | E15: 3976733.3 | F15: 0 | G15: 21820000
B16: 23120000 | C16: Immo en cours Analamahitsy | D16: 2699631.9 | G16: 23120000
B17: 23160000 | C17: Immo en cours Alarobia | D17: 1.3951661e+08 | G17: 23160000
B18: 23170000 | C18: Immo en cours Tamatave | D18: 4.4166799e+08 | G18: 23170000
B19: 23190000 | C19: Immo en cours Ford Dauphin | D19: 1661495 | G19: 23190000
A20: 230000 | B20: 23000000 | C20: Immo en cours | D20: 6.3276286e+09 | E20: 6.0768375e+09 | F20: 0 | G20: 23200000
A21: 231000 | B21: 23100000 | C21: Immo. corporelles en cours | D21: 1.7163699e+09 | E21: 1664191.2 | F21: 0 | G21: 23200000
A22: 231100 | B22: 23110000 | C22: Immo en cours RéhabilitatioMantasoa | D22: 1.5315954e+08 | E22: 32494477 | F22: 0 | G22: 23200000
A23: 231300 | B23: 23130000 | C23: Immo en cours Mahitsy | D23: 19506500 | E23: 19506500 | F23: 0 | G23: 23200000
B24: 23210000 | C24: Immo en cours-villa MSI Ivandry | D24: 11021337 | G24: 23200000
A25: 281110 | B25: 28111000 | C25: Amort agencement terrain | D25: -53105016 | E25: -35421745 | F25: -29394578 | G25: 28120000
A26: 281300 | B26: 28130000 | C26: Amorts Batiments&Constructions | D26: -4.4607462e+08 | E26: -89395987 | F26: -44697993 | G26: 28130000
A27: 281500 | B27: 28150000 | C27: Amort Agenc Amenag installation | D27: -20937300 | E27: -12730221 | F27: -8021687.4 | G27: 28150000
A28: 281810 | B28: 28181000 | C28: Amort. Matériels & outillages | D28: -1823135.7 | E28: -1139335.1 | F28: -777960.07 | G28: 28154000
A29: 281880 | B29: 28188000 | C29: Amort Materiel&mobilier de logement | D29: -3457918 | E29: -20337.96 | F29: 0 | G29: 28182000
A30: 401100 | B30: 40110000 | C30: Fournisseurs Locaux | D30: -3.4096483e+08 | E30: -3.8834177e+08 | F30: -5.8746546e+08 | G30: 40110000
B31: 40120000 | C31: Fournisseurs ‚trangers | D31: -89116538 | G31: 40120000
B32: 40310000 | C32: F/sseurs effets … payer BMOI | D32: -1242170.7 | G32: 40310000
A33: 404000 | B33: 40400000 | C33: Fournisseurs d'immobilisations | D33: -454000000 | E33: -554000000 | F33: 0 | G33: 40400000
A34: 408000 | B34: 40800000 | C34: F/sseurs fact à recevoir | D34: -5.0870851e+09 | E34: -5019014000 | F34: -7322459.6 | G34: 40810000
A35: 409000 | B35: 40900000 | C35: Avances et acomptes fournisseurs | D35: 10981327 | E35: 0 | F35: 0 | G35: 40910000
